/*
1.
Caso nenhuam exceção seja lançada em um bloco try, o controle de execução prossegue normalmente 
para a próxima instrução após o bloco try-catch. Se houver um bloco finally, ele será executado 
antes de continuar com as instruções seguintes.


2. Se uma exceção ocorrer sem um bloco catch para tratá-la, ela será propagada até que ela seja
capturada por algum catch de algum método chamador em um nível superior. Caso nenhum catch capture
essa exceção, o programa sera encerrado com uma mensagem de erro.



*/

